<?xml version="1.0" ?>
<robot name="testship" xmlns:xacro="http://www.ros.org/wiki/xacro">

<xacro:include filename="$(find testship_description)/urdf/materials.xacro" />
<xacro:include filename="$(find testship_description)/urdf/testship.trans" />
<xacro:include filename="$(find testship_description)/urdf/testship.gazebo" />
<link name="base_link">
  <inertial>
    <origin xyz="0.016734464251040394 0.175376110748741 0.05951090852491351" rpy="0 0 0"/>
    <mass value="24.63020025957244"/>
    <inertia ixx="0.766917" iyy="1.397795" izz="1.945279" ixy="0.000264" iyz="0.000272" ixz="-0.062443"/>
  </inertial>
  <visual>
    <origin xyz="0 0 0" rpy="0 0 0"/>
    <geometry>
      <mesh filename="file://$(find testship_description)/meshes/base_link.stl" scale="0.001 0.001 0.001"/>
    </geometry>
    <material name="silver"/>
  </visual>
  <collision>
    <origin xyz="0 0 0" rpy="0 0 0"/>
    <geometry>
      <mesh filename="file://$(find testship_description)/meshes/base_link.stl" scale="0.001 0.001 0.001"/>
    </geometry>
  </collision>
</link>

<link name="top_1">
  <inertial>
    <origin xyz="-0.03384244292889854 6.85523642948993e-05 0.002249928723865563" rpy="0 0 0"/>
    <mass value="0.34029539991835445"/>
    <inertia ixx="0.001651" iyy="0.01217" izz="0.013819" ixy="-6e-06" iyz="-0.0" ixz="0.0"/>
  </inertial>
  <visual>
    <origin xyz="-0.097793 -0.175487 -0.205194" rpy="0 0 0"/>
    <geometry>
      <mesh filename="file://$(find testship_description)/meshes/top_1.stl" scale="0.001 0.001 0.001"/>
    </geometry>
    <material name="silver"/>
  </visual>
  <collision>
    <origin xyz="-0.097793 -0.175487 -0.205194" rpy="0 0 0"/>
    <geometry>
      <mesh filename="file://$(find testship_description)/meshes/top_1.stl" scale="0.001 0.001 0.001"/>
    </geometry>
  </collision>
</link>

<link name="leftphcir_1">
  <inertial>
    <origin xyz="-3.976662354965299e-08 9.141719398142456e-08 -0.03383213045082126" rpy="0 0 0"/>
    <mass value="0.23329485266794953"/>
    <inertia ixx="7.5e-05" iyy="7.5e-05" izz="5.7e-05" ixy="-0.0" iyz="-0.0" ixz="0.0"/>
  </inertial>
  <visual>
    <origin xyz="0.452267 -0.362987 -0.025194" rpy="0 0 0"/>
    <geometry>
      <mesh filename="file://$(find testship_description)/meshes/leftphcir_1.stl" scale="0.001 0.001 0.001"/>
    </geometry>
    <material name="silver"/>
  </visual>
  <collision>
    <origin xyz="0.452267 -0.362987 -0.025194" rpy="0 0 0"/>
    <geometry>
      <mesh filename="file://$(find testship_description)/meshes/leftphcir_1.stl" scale="0.001 0.001 0.001"/>
    </geometry>
  </collision>
</link>

<link name="rightphcir_1">
  <inertial>
    <origin xyz="-3.9766623216586083e-08 1.0963459409762955e-07 -0.03383213045082052" rpy="0 0 0"/>
    <mass value="0.23329485266794966"/>
    <inertia ixx="7.5e-05" iyy="7.5e-05" izz="5.7e-05" ixy="-0.0" iyz="-0.0" ixz="0.0"/>
  </inertial>
  <visual>
    <origin xyz="0.452267 0.012013 -0.025194" rpy="0 0 0"/>
    <geometry>
      <mesh filename="file://$(find testship_description)/meshes/rightphcir_1.stl" scale="0.001 0.001 0.001"/>
    </geometry>
    <material name="silver"/>
  </visual>
  <collision>
    <origin xyz="0.452267 0.012013 -0.025194" rpy="0 0 0"/>
    <geometry>
      <mesh filename="file://$(find testship_description)/meshes/rightphcir_1.stl" scale="0.001 0.001 0.001"/>
    </geometry>
  </collision>
</link>

<link name="lidar_1">
  <inertial>
    <origin xyz="-0.0005646458627516782 -1.4528401645980127e-05 0.019299074424405455" rpy="0 0 0"/>
    <mass value="1.2982579906067508"/>
    <inertia ixx="0.000618" iyy="0.00059" izz="0.000863" ixy="0.0" iyz="0.0" ixz="1.7e-05"/>
  </inertial>
  <visual>
    <origin xyz="-0.31835 -0.170109 -0.209694" rpy="0 0 0"/>
    <geometry>
      <mesh filename="file://$(find testship_description)/meshes/lidar_1.stl" scale="0.001 0.001 0.001"/>
    </geometry>
    <material name="silver"/>
  </visual>
  <collision>
    <origin xyz="-0.31835 -0.170109 -0.209694" rpy="0 0 0"/>
    <geometry>
      <mesh filename="file://$(find testship_description)/meshes/lidar_1.stl" scale="0.001 0.001 0.001"/>
    </geometry>
  </collision>
</link>

<link name="camerastand_1">
  <inertial>
    <origin xyz="0.0034318487099775086 0.026010390379762938 0.21468627057848771" rpy="0 0 0"/>
    <mass value="0.03710493249188583"/>
    <inertia ixx="0.000118" iyy="8.1e-05" izz="4.4e-05" ixy="-0.0" iyz="-0.0" ixz="-4e-06"/>
  </inertial>
  <visual>
    <origin xyz="0.202207 -0.149487 -0.209694" rpy="0 0 0"/>
    <geometry>
      <mesh filename="file://$(find testship_description)/meshes/camerastand_1.stl" scale="0.001 0.001 0.001"/>
    </geometry>
    <material name="silver"/>
  </visual>
  <collision>
    <origin xyz="0.202207 -0.149487 -0.209694" rpy="0 0 0"/>
    <geometry>
      <mesh filename="file://$(find testship_description)/meshes/camerastand_1.stl" scale="0.001 0.001 0.001"/>
    </geometry>
  </collision>
</link>

<link name="leftph_1">
  <inertial>
    <origin xyz="-0.005787625114010819 -0.00047965048473014305 -0.05043663542580278" rpy="0 0 0"/>
    <mass value="0.6260636804872378"/>
    <inertia ixx="0.00051" iyy="0.000766" izz="0.000346" ixy="-2.1e-05" iyz="-8e-06" ixz="-9.3e-05"/>
  </inertial>
  <visual>
    <origin xyz="0.452267 -0.362987 0.022306" rpy="0 0 0"/>
    <geometry>
      <mesh filename="file://$(find testship_description)/meshes/leftph_1.stl" scale="0.001 0.001 0.001"/>
    </geometry>
    <material name="silver"/>
  </visual>
  <collision>
    <origin xyz="0.452267 -0.362987 0.022306" rpy="0 0 0"/>
    <geometry>
      <mesh filename="file://$(find testship_description)/meshes/leftph_1.stl" scale="0.001 0.001 0.001"/>
    </geometry>
  </collision>
</link>

<link name="rightph_1">
  <inertial>
    <origin xyz="-0.005787625697734833 -0.00047963210089440114 -0.05043663492246866" rpy="0 0 0"/>
    <mass value="0.626063680487237"/>
    <inertia ixx="0.00051" iyy="0.000766" izz="0.000346" ixy="-2.1e-05" iyz="-8e-06" ixz="-9.3e-05"/>
  </inertial>
  <visual>
    <origin xyz="0.452267 0.012013 0.022306" rpy="0 0 0"/>
    <geometry>
      <mesh filename="file://$(find testship_description)/meshes/rightph_1.stl" scale="0.001 0.001 0.001"/>
    </geometry>
    <material name="silver"/>
  </visual>
  <collision>
    <origin xyz="0.452267 0.012013 0.022306" rpy="0 0 0"/>
    <geometry>
      <mesh filename="file://$(find testship_description)/meshes/rightph_1.stl" scale="0.001 0.001 0.001"/>
    </geometry>
  </collision>
</link>

<link name="leftprop_1">
  <inertial>
    <origin xyz="-0.012762549912910592 -0.0007089162358155376 9.097354075347786e-05" rpy="0 0 0"/>
    <mass value="0.06590576270790414"/>
    <inertia ixx="1.5e-05" iyy="1.1e-05" izz="1.1e-05" ixy="0.0" iyz="-1e-06" ixz="-0.0"/>
  </inertial>
  <visual>
    <origin xyz="0.508474 -0.358328 0.090106" rpy="0 0 0"/>
    <geometry>
      <mesh filename="file://$(find testship_description)/meshes/leftprop_1.stl" scale="0.001 0.001 0.001"/>
    </geometry>
    <material name="silver"/>
  </visual>
  <collision>
    <origin xyz="0.508474 -0.358328 0.090106" rpy="0 0 0"/>
    <geometry>
      <mesh filename="file://$(find testship_description)/meshes/leftprop_1.stl" scale="0.001 0.001 0.001"/>
    </geometry>
  </collision>
</link>

<link name="rightprop_1">
  <inertial>
    <origin xyz="-0.012943746553238156 -0.0010731097718223136 2.2777126962303385e-08" rpy="0 0 0"/>
    <mass value="0.06590837354443096"/>
    <inertia ixx="1.5e-05" iyy="1.1e-05" izz="1.1e-05" ixy="0.0" iyz="-0.0" ixz="-0.0"/>
  </inertial>
  <visual>
    <origin xyz="0.508474 0.016672 0.090106" rpy="0 0 0"/>
    <geometry>
      <mesh filename="file://$(find testship_description)/meshes/rightprop_1.stl" scale="0.001 0.001 0.001"/>
    </geometry>
    <material name="silver"/>
  </visual>
  <collision>
    <origin xyz="0.508474 0.016672 0.090106" rpy="0 0 0"/>
    <geometry>
      <mesh filename="file://$(find testship_description)/meshes/rightprop_1.stl" scale="0.001 0.001 0.001"/>
    </geometry>
  </collision>
</link>

<link name="depthcamera_1">
  <inertial>
    <origin xyz="0.0027436562400410813 -0.001814687981789187 0.020612462370148465" rpy="0 0 0"/>
    <mass value="0.3595663734702526"/>
    <inertia ixx="0.000774" iyy="0.000116" izz="0.000709" ixy="-6e-06" iyz="1.2e-05" ixz="2.8e-05"/>
  </inertial>
  <visual>
    <origin xyz="0.178553 -0.175487 -0.438073" rpy="0 0 0"/>
    <geometry>
      <mesh filename="file://$(find testship_description)/meshes/depthcamera_1.stl" scale="0.001 0.001 0.001"/>
    </geometry>
    <material name="silver"/>
  </visual>
  <collision>
    <origin xyz="0.178553 -0.175487 -0.438073" rpy="0 0 0"/>
    <geometry>
      <mesh filename="file://$(find testship_description)/meshes/depthcamera_1.stl" scale="0.001 0.001 0.001"/>
    </geometry>
  </collision>
</link>

<joint name="Rigid 34" type="fixed">
  <origin xyz="0.097793 0.175487 0.205194" rpy="0 0 0"/>
  <parent link="base_link"/>
  <child link="top_1"/>
</joint>

<joint name="Rigid 35" type="fixed">
  <origin xyz="-0.452267 0.362987 0.025194" rpy="0 0 0"/>
  <parent link="base_link"/>
  <child link="leftphcir_1"/>
</joint>

<joint name="Rigid 36" type="fixed">
  <origin xyz="-0.452267 -0.012013 0.025194" rpy="0 0 0"/>
  <parent link="base_link"/>
  <child link="rightphcir_1"/>
</joint>

<joint name="Rigid 37" type="fixed">
  <origin xyz="0.220557 -0.005378 0.0045" rpy="0 0 0"/>
  <parent link="top_1"/>
  <child link="lidar_1"/>
</joint>

<joint name="Rigid 38" type="fixed">
  <origin xyz="-0.3 -0.026 0.0045" rpy="0 0 0"/>
  <parent link="top_1"/>
  <child link="camerastand_1"/>
</joint>

<joint name="Revolute 39" type="continuous">
  <origin xyz="0.0 0.0 -0.0475" rpy="0 0 0"/>
  <parent link="leftphcir_1"/>
  <child link="leftph_1"/>
  <axis xyz="0.0 -0.0 -1.0"/>
</joint>

<joint name="Revolute 40" type="continuous">
  <origin xyz="0.0 0.0 -0.0475" rpy="0 0 0"/>
  <parent link="rightphcir_1"/>
  <child link="rightph_1"/>
  <axis xyz="0.0 -0.0 -1.0"/>
</joint>

<joint name="Revolute 41" type="continuous">
  <origin xyz="-0.056207 -0.004659 -0.0678" rpy="0 0 0"/>
  <parent link="leftph_1"/>
  <child link="leftprop_1"/>
  <axis xyz="-0.996582 -0.082608 0.0"/>
</joint>

<joint name="Revolute 42" type="continuous">
  <origin xyz="-0.056207 -0.004659 -0.0678" rpy="0 0 0"/>
  <parent link="rightph_1"/>
  <child link="rightprop_1"/>
  <axis xyz="-0.996582 -0.082608 0.0"/>
</joint>

<joint name="Rigid 43" type="fixed">
  <origin xyz="0.023654 0.026 0.228379" rpy="0 0 0"/>
  <parent link="camerastand_1"/>
  <child link="depthcamera_1"/>
</joint>

</robot>
